Workbook

Sheet Consumidores Inadimplentes
A2: Indicador Serasa Experian de Inadimplência do Consumidor | K2: Por Faixa Etária (milhões)
A3: Mês | B3: Consumidores Inadimplentes (milhões) | C3: Dívidas Negativadas (milhões) | D3: Dívidas Negativadas (R$ bilhões) | E3: Dívida Média (por CPF) | F3: Dívida Média (R$) | G3: Ticket Médio (R$) | H3: % da População Adulta | I3: Gênero (milhões) F M | K3: Até 25 anos | L3: 26 - 40 anos | M3: 41 - 60 anos | N3: acima de 60 anos
A4: 42370 | B4: n.d. | C4: n.d. | D4: n.d. | E4: n.d. | F4: n.d. | G4: n.d. | H4: n.d. | I4: n.d. | J4: n.d. | K4: n.d. | L4: n.d. | M4: n.d. | N4: n.d.
A5: 42401 | B5: n.d. | C5: n.d. | D5: n.d. | E5: n.d. | F5: n.d. | G5: n.d. | H5: n.d. | I5: n.d. | J5: n.d. | K5: n.d. | L5: n.d. | M5: n.d. | N5: n.d.
A6: 42430 | B6: 59.190914 | C6: 231.328 | D6: 214.55408 | E6: =C6/B6 -> 3.9081674 | F6: =1000*D6/B6 -> 3624.7806 | G6: =F6/E6 -> 927.48857 | H6: n.d. | I6: n.d. | J6: n.d. | K6: n.d. | L6: n.d. | M6: n.d. | N6: n.d.
A7: 42461 | B7: 59.735 | C7: 233.427 | D7: 224.57353 | E7: =C7/B7 -> 3.907709 | F7: =1000*D7/B7 -> 3759.4966 | G7: =F7/E7 -> 962.07177 | H7: n.d. | I7: n.d. | J7: n.d. | K7: n.d. | L7: n.d. | M7: n.d. | N7: n.d.
A8: 42491 | B8: 58.889 | C8: 228.928 | D8: 225.06923 | E8: =C8/B8 -> 3.8874493 | F8: =1000*D8/B8 -> 3821.9231 | G8: =F8/E8 -> 983.14417 | H8: n.d. | I8: n.d. | J8: n.d. | K8: n.d. | L8: n.d. | M8: n.d. | N8: n.d.
A9: 42522 | B9: 59.072 | C9: 229.393 | D9: 224.76835 | E9: =C9/B9 -> 3.883278 | F9: =1000*D9/B9 -> 3804.9896 | G9: =F9/E9 -> 979.83961 | H9: n.d. | I9: n.d. | J9: n.d. | K9: n.d. | L9: n.d. | M9: n.d. | N9: n.d.
A10: 42552 | B10: 58.746 | C10: 227.049 | D10: 224.66243 | E10: =C10/B10 -> 3.864927 | F10: =1000*D10/B10 -> 3824.3017 | G10: =F10/E10 -> 989.48875 | H10: n.d. | I10: n.d. | J10: n.d. | K10: n.d. | L10: n.d. | M10: n.d. | N10: n.d.
A11: 42583 | B11: 58.631 | C11: 226.204 | D11: 225.86955 | E11: =C11/B11 -> 3.8580955 | F11: =1000*D11/B11 -> 3852.3913 | G11: =F11/E11 -> 998.52148 | H11: n.d. | I11: n.d. | J11: n.d. | K11: n.d. | L11: n.d. | M11: n.d. | N11: n.d.
A12: 42614 | B12: 58.921 | C12: 225.679 | D12: 227.6914 | E12: =C12/B12 -> 3.8301964 | F12: =1000*D12/B12 -> 3864.3506 | G12: =F12/E12 -> 1008.9171 | H12: n.d. | I12: n.d. | J12: n.d. | K12: n.d. | L12: n.d. | M12: n.d. | N12: n.d.
A13: 42644 | B13: 58.661 | C13: 218.711 | D13: 227.86876 | E13: =C13/B13 -> 3.7283885 | F13: =1000*D13/B13 -> 3884.5018 | G13: =F13/E13 -> 1041.8715 | H13: n.d. | I13: n.d. | J13: n.d. | K13: n.d. | L13: n.d. | M13: n.d. | N13: n.d.
A14: 42675 | B14: 59.344 | C14: 228.652 | D14: 229.54093 | E14: =C14/B14 -> 3.8529927 | F14: =1000*D14/B14 -> 3867.9721 | G14: =F14/E14 -> 1003.8877 | H14: 0.39746255 | I14: n.d. | J14: n.d. | K14: n.d. | L14: n.d. | M14: n.d. | N14: n.d.
A15: 42705 | B15: 58.976 | C15: 229.45 | D15: 228.34041 | E15: =C15/B15 -> 3.8905657 | F15: =1000*D15/B15 -> 3871.7514 | G15: =F15/E15 -> 995.16413 | H15: 0.3945748 | I15: n.d. | J15: n.d. | K15: n.d. | L15: n.d. | M15: n.d. | N15: n.d.
A16: 42736 | B16: 59.022 | C16: 227.612 | D16: 229.12089 | E16: =C16/B16 -> 3.8563925 | F16: =1000*D16/B16 -> 3881.9575 | G16: =F16/E16 -> 1006.6292 | H16: 0.3944596 | I16: n.d. | J16: n.d. | K16: n.d. | L16: n.d. | M16: n.d. | N16: n.d.
A17: 42767 | B17: 59.119 | C17: 227.323 | D17: 229.34031 | E17: =C17/B17 -> 3.8451767 | F17: =1000*D17/B17 -> 3879.2995 | G17: =F17/E17 -> 1008.8742 | H17: 0.39468463 | I17: n.d. | J17: n.d. | K17: n.d. | L17: n.d. | M17: n.d. | N17: n.d.
A18: 42795 | B18: 59.12 | C18: 225.86 | D18: 230.58245 | E18: =C18/B18 -> 3.8203654 | F18: =1000*D18/B18 -> 3900.2444 | G18: =F18/E18 -> 1020.9087 | H18: 0.39426846 | I18: n.d. | J18: n.d. | K18: n.d. | L18: n.d. | M18: n.d. | N18: n.d.
A19: 42826 | B19: 59.426 | C19: 225.852 | D19: 228.59267 | E19: =C19/B19 -> 3.8005587 | F19: =1000*D19/B19 -> 3846.6777 | G19: =F19/E19 -> 1012.1348 | H19: 0.39588455 | I19: n.d. | J19: n.d. | K19: n.d. | L19: n.d. | M19: n.d. | N19: n.d.
A20: 42856 | B20: 60.309 | C20: 229.928 | D20: 233.24935 | E20: =C20/B20 -> 3.812499 | F20: =1000*D20/B20 -> 3867.5712 | G20: =F20/E20 -> 1014.4452 | H20: 0.40133643 | I20: n.d. | J20: n.d. | K20: n.d. | L20: n.d. | M20: n.d. | N20: n.d.
A21: 42887 | B21: 59.972 | C21: 228.455 | D21: 232.24693 | E21: =C21/B21 -> 3.809361 | F21: =1000*D21/B21 -> 3872.5894 | G21: =F21/E21 -> 1016.5982 | H21: 0.39866612 | I21: n.d. | J21: n.d. | K21: n.d. | L21: n.d. | M21: n.d. | N21: n.d.
A22: 42917 | B22: 59.785 | C22: 226.939 | D22: 230.88546 | E22: =C22/B22 -> 3.7959187 | F22: =1000*D22/B22 -> 3861.9296 | G22: =F22/E22 -> 1017.39 | H22: 0.39699709 | I22: n.d. | J22: n.d. | K22: n.d. | L22: n.d. | M22: n.d. | N22: n.d.
A23: 42948 | B23: 59.794 | C23: 225.519 | D23: 229.66715 | E23: =C23/B23 -> 3.7715992 | F23: =1000*D23/B23 -> 3840.9732 | G23: =F23/E23 -> 1018.3938 | H23: 0.39665844 | I23: n.d. | J23: n.d. | K23: n.d. | L23: n.d. | M23: n.d. | N23: n.d.
A24: 42979 | B24: 59.837 | C24: 225.523 | D24: 227.19387 | E24: =C24/B24 -> 3.7689557 | F24: =1000*D24/B24 -> 3796.8793 | G24: =F24/E24 -> 1007.4089 | H24: 0.39654533 | I24: n.d. | J24: n.d. | K24: n.d. | L24: n.d. | M24: n.d. | N24: n.d.
A25: 43009 | B25: 60.364 | C25: 226.558 | D25: 228.61925 | E25: =C25/B25 -> 3.7531973 | F25: =1000*D25/B25 -> 3787.3443 | G25: =F25/E25 -> 1009.0981 | H25: 0.3996363 | I25: n.d. | J25: n.d. | K25: n.d. | L25: n.d. | M25: n.d. | N25: n.d.
... A39: 43435 | B39: 62.473341 | C39: 233.32314 | D39: 246.21291 | E39: =C39/B39 -> 3.7347633 | F39: =1000*D39/B39 -> 3941.0876 | G39: =F39/E39 -> 1055.2443 | H39: 0.40858904 | I39: n.d. | J39: n.d. | K39: n.d. | L39: n.d. | M39: n.d. | N39: n.d.
A40: 43466 | B40: 62.176389 | C40: 229.19332 | D40: 244.12878 | E40: =C40/B40 -> 3.6861794 | F40: =1000*D40/B40 -> 3926.3905 | G40: =F40/E40 -> 1065.1653 | H40: 0.40622983 | I40: 30.596152 | J40: 31.580237 | K40: 8.632275 | L40: 23.417264 | M40: 20.936872 | N40: 9.189978
A41: 43497 | B41: 62.172903 | C41: 228.61271 | D41: 243.23216 | E41: =C41/B41 -> 3.6770473 | F41: =1000*D41/B41 -> 3912.1892 | G41: =F41/E41 -> 1063.9486 | H41: 0.40574887 | I41: 30.605162 | J41: 31.567741 | K41: 8.584212 | L41: 23.391394 | M41: 20.977382 | N41: 9.219915
A42: 43525 | B42: 62.960081 | C42: 231.16343 | D42: 248.6806 | E42: =C42/B42 -> 3.6715872 | F42: =1000*D42/B42 -> 3949.8139 | G42: =F42/E42 -> 1075.7783 | H42: 0.41034176 | I42: 30.994635 | J42: 31.965446 | K42: 8.647358 | L42: 23.619362 | M42: 21.298095 | N42: 9.395266
A43: 43556 | B43: 63.205404 | C43: 229.59013 | D43: 247.92447 | E43: =C43/B43 -> 3.6324447 | F43: =1000*D43/B43 -> 3922.5201 | G43: =F43/E43 -> 1079.8568 | H43: 0.41119737 | I43: 31.121997 | J43: 32.083407 | K43: 8.623733 | L43: 23.653625 | M43: 21.405728 | N43: 9.522318
A44: 43586 | B44: 63.374619 | C44: 230.03009 | D44: 250.7214 | E44: =C44/B44 -> 3.629688 | F44: =1000*D44/B44 -> 3956.18 | G44: =F44/E44 -> 1089.9504 | H44: 0.40905531 | I44: 31.206888 | J44: 32.167731 | K44: 8.591269 | L44: 23.673098 | M44: 21.495635 | N44: 9.614617
A45: 43617 | B45: 63.450581 | C45: 229.53571 | D45: 251.78629 | E45: =C45/B45 -> 3.617551 | F45: =1000*D45/B45 -> 3968.2267 | G45: =F45/E45 -> 1096.9373 | H45: 0.41233677 | I45: 31.238109 | J45: 32.212472 | K45: 8.589862 | L45: 23.699304 | M45: 21.531008 | N45: 9.630407
A46: 43647 | B46: 63.463368 | C46: 228.92486 | D46: 252.09312 | E46: =C46/B46 -> 3.6071969 | F46: =1000*D46/B46 -> 3972.2619 | G46: =F46/E46 -> 1101.2046 | H46: 0.41149392 | I46: 31.253575 | J46: 32.209793 | K46: 8.582518 | L46: 23.665293 | M46: 21.54809 | N46: 9.667467
A47: 43678 | B47: 63.427939 | C47: 229.16913 | D47: 256.16655 | E47: =C47/B47 -> 3.6130628 | F47: =1000*D47/B47 -> 4038.7021 | G47: =F47/E47 -> 1117.8057 | H47: 0.41084099 | I47: 31.212792 | J47: 32.215147 | K47: 8.531247 | L47: 23.636213 | M47: 21.578072 | N47: 9.682407
A48: 43709 | B48: 63.206609 | C48: 226.26364 | D48: 252.68665 | E48: =C48/B48 -> 3.5797465 | F48: =1000*D48/B48 -> 3997.7884 | G48: =F48/E48 -> 1116.7798 | H48: 0.40902572 | I48: 31.065532 | J48: 32.141077 | K48: 8.461761 | L48: 23.563721 | M48: 21.542809 | N48: 9.638318
A49: 43739 | B49: 63.85141 | C49: 228.22774 | D49: 254.94453 | E49: =C49/B49 -> 3.5743571 | F49: =1000*D49/B49 -> 3992.7785 | G49: =F49/E49 -> 1117.062 | H49: 0.41281317 | I49: 31.390098 | J49: 32.461312 | K49: 8.564821 | L49: 23.714484 | M49: 21.765565 | N49: 9.80654
A50: 43770 | B50: 63.840968 | C50: 226.60013 | D50: 256.2712 | E50: =C50/B50 -> 3.549447 | F50: =1000*D50/B50 -> 4014.2123 | G50: =F50/E50 -> 1130.9402 | H50: 0.4123608 | I50: 31.427759 | J50: 32.413209 | K50: 8.562149 | L50: 23.641386 | M50: 21.794938 | N50: 9.842495
A51: 43800 | B51: 63.307343 | C51: 224.84153 | D51: 255.91063 | E51: =C51/B51 -> 3.5515869 | F51: =1000*D51/B51 -> 4042.353 | G51: =F51/E51 -> 1138.1822 | H51: 0.40853269 | I51: 31.084271 | J51: 32.223072 | K51: 8.465536 | L51: 23.396888 | M51: 21.655504 | N51: 9.789415
... A75: 44531 | B75: 63.970854 | C75: 213.58677 | D75: 251.94994 | E75: =C75/B75 -> 3.3388138 | F75: =1000*D75/B75 -> 3938.5114 | G75: =F75/E75 -> 1179.614 | H75: 0.40495241 | I75: 32.054439 | J75: 31.916415 | K75: 7.993807 | L75: 22.77077 | M75: 22.096777 | N75: 11.1095
A76: 44562 | B76: =64.817442 -> 64.817442 | C76: 219.50181 | D76: 260.72953 | E76: =C76/B76 -> 3.3864621 | F76: =1000*D76/B76 -> 4022.5212 | G76: =F76/E76 -> 1187.8241 | H76: 0.41002541 | I76: 32.484546 | J76: 32.332896 | K76: 8.184342 | L76: 23.074751 | M76: 22.325069 | N76: 11.23328
A77: 44593 | B77: 65.169146 | C77: 221.34239 | D77: 263.41861 | E77: =C77/B77 -> 3.3964292 | F77: =1000*D77/B77 -> 4042.0756 | G77: =F77/E77 -> 1190.0956 | H77: 0.41196273 | I77: 32.688611 | J77: 32.480535 | K77: 8.295033 | L77: 23.210111 | M77: 22.409154 | N77: 11.254848
...

Sheet Setores
A2: Indicador Serasa Experian de Inadimplência do Consumidor - Participação dos Setores na Inadimplência Total (%)
A3: Mês | B3: Bancos / Cartões (A) | C3: Utilities (B) | D3: Telefonia (C) | E3: Varejo (D) | F3: Serviços (E) | G3: Financeiras (F) | H3: Securitizadoras (G) | I3: Cooperativas (H) | J3: Outros (I) | K3: Total Financeiro (A) + (F) | L3: Total não Financeiro (B) + (C) + (D) + (E) + (G) + (H) + (I)
A4: 43101 | B4: 0.28182986 | C4: 0.18942799 | D4: 0.11873121 | E4: 0.13287314 | F4: 0.10959348 | G4: 0.076161868 | H4: 0.045216287 | I4: n.d. | J4: 0.046166153 | K4: =G4+B4 -> 0.35799173 | L4: =SUM(C4:F4)+H4+J4 -> 0.64200827
A5: 43132 | B5: 0.28348071 | C5: 0.19102838 | D5: 0.1191261 | E5: 0.13272149 | F5: 0.10760578 | G5: 0.076637943 | H5: 0.043344885 | I5: n.d. | J5: 0.046054712 | K5: =G5+B5 -> 0.36011865 | L5: =SUM(C5:F5)+H5+J5 -> 0.63988135
A6: 43160 | B6: 0.28096516 | C6: 0.19036347 | D6: 0.11708486 | E6: 0.13168628 | F6: 0.10580787 | G6: 0.090724273 | H6: 0.038852037 | I6: n.d. | J6: 0.044516051 | K6: =G6+B6 -> 0.37168943 | L6: =SUM(C6:F6)+H6+J6 -> 0.62831057
A7: 43191 | B7: 0.28174605 | C7: 0.19047978 | D7: 0.11523085 | E7: 0.13010568 | F7: 0.10284966 | G7: 0.092461 | H7: 0.043092661 | I7: n.d. | J7: 0.044034321 | K7: =G7+B7 -> 0.37420705 | L7: =SUM(C7:F7)+H7+J7 -> 0.62579295
A8: 43221 | B8: 0.28091572 | C8: 0.19209322 | D8: 0.11557893 | E8: 0.13135549 | F8: 0.10140193 | G8: 0.092603117 | H8: 0.04199766 | I8: n.d. | J8: 0.04405392 | K8: =G8+B8 -> 0.37351884 | L8: =SUM(C8:F8)+H8+J8 -> 0.62648116
A9: 43252 | B9: 0.27856132 | C9: 0.19623064 | D9: 0.11550356 | E9: 0.13071561 | F9: 0.10233005 | G9: 0.092343312 | H9: 0.04019503 | I9: n.d. | J9: 0.044120481 | K9: =G9+B9 -> 0.37090463 | L9: =SUM(C9:F9)+H9+J9 -> 0.62909537
A10: 43282 | B10: 0.28123573 | C10: 0.19366306 | D10: 0.1161453 | E10: 0.13065656 | F10: 0.10323611 | G10: 0.091947947 | H10: 0.03890085 | I10: n.d. | J10: 0.044214445 | K10: =G10+B10 -> 0.37318368 | L10: =SUM(C10:F10)+H10+J10 -> 0.62681633
A11: 43313 | B11: 0.2804623 | C11: 0.19147244 | D11: 0.1201291 | E11: 0.12982745 | F11: 0.10303651 | G11: 0.094170593 | H11: 0.037470387 | I11: n.d. | J11: 0.043431213 | K11: =G11+B11 -> 0.37463289 | L11: =SUM(C11:F11)+H11+J11 -> 0.62536711
A12: 43344 | B12: 0.28116963 | C12: 0.19144252 | D12: 0.11789787 | E12: 0.1298349 | F12: 0.10490309 | G12: 0.093439356 | H12: 0.036477195 | I12: n.d. | J12: 0.044835432 | K12: =G12+B12 -> 0.37460898 | L12: =SUM(C12:F12)+H12+J12 -> 0.62539102
A13: 43374 | B13: 0.2693499 | C13: 0.1916956 | D13: 0.13101379 | E13: 0.12758659 | F13: 0.1037388 | G13: 0.091683328 | H13: 0.038893668 | I13: n.d. | J13: 0.04603832 | K13: =G13+B13 -> 0.36103323 | L13: =SUM(C13:F13)+H13+J13 -> 0.63896677
A14: 43405 | B14: 0.27509202 | C14: 0.19639185 | D14: 0.1279363 | E14: 0.1219453 | F14: 0.1020555 | G14: 0.093035563 | H14: 0.038513338 | I14: n.d. | J14: 0.045030136 | K14: =G14+B14 -> 0.36812758 | L14: =SUM(C14:F14)+H14+J14 -> 0.63187242
A15: 43435 | B15: 0.26925056 | C15: 0.20408137 | D15: 0.12962142 | E15: 0.11754746 | F15: 0.10335937 | G15: 0.0935408 | H15: 0.036974766 | I15: n.d. | J15: 0.045624251 | K15: =G15+B15 -> 0.36279136 | L15: =SUM(C15:F15)+H15+J15 -> 0.63720864
... A82: 45474 | B82: 0.28440225 | C82: 0.21850434 | D82: 0.045970961 | E82: 0.10506028 | F82: 0.1209009 | G82: 0.17810869 | H82: 0.012303306 | I82: n.d. | J82: 0.034749279 | K82: =G82+B82 -> 0.46251094 | L82: =SUM(C82:F82)+H82+J82 -> 0.53748906
A83: 45505 | B83: 0.2798209 | C83: 0.21702245 | D83: 0.051671119 | E83: 0.10527433 | F83: 0.1086703 | G83: 0.17480997 | H83: 0.015546863 | I83: 0.018702855 | J83: 0.028481211 | K83: =G83+B83 -> 0.45463087 | L83: =SUM(C83:F83)+H83+J83+I83 -> 0.54536913
A84: 45536 | B84: 0.28026247 | C84: 0.2176781 | D84: 0.05044114 | E84: 0.10440239 | F84: 0.10829713 | G84: 0.17510614 | H84: 0.016301385 | I84: 0.018845868 | J84: 0.028665377 | K84: =G84+B84 -> 0.45536861 | L84: =SUM(C84:F84)+H84+J84+I84 -> 0.54463139
A85: 45566 | B85: 0.2785634 | C85: 0.21675861 | D85: 0.049224372 | E85: 0.10335387 | F85: 0.10906754 | G85: 0.17648635 | H85: 0.018927641 | I85: 0.019078805 | J85: 0.028539404 | K85: =G85+B85 -> 0.45504975 | L85: =SUM(C85:F85)+H85+J85+I85 -> 0.54495025
A86: 45597 | B86: 0.28621082 | C86: 0.20278908 | D86: 0.049214618 | E86: 0.10360188 | F86: 0.1114627 | G86: 0.17995904 | H86: 0.018559592 | I86: 0.019249187 | J86: 0.028953079 | K86: =G86+B86 -> 0.46616986 | L86: =SUM(C86:F86)+H86+J86+I86 -> 0.53383014
A87: 45627 | B87: 0.27434075 | C87: 0.2206185 | D87: 0.048695597 | E87: 0.10078232 | F87: 0.11029311 | G87: 0.17987693 | H87: 0.0179398 | I87: 0.019016942 | J87: 0.028436042 | K87: =G87+B87 -> 0.45421769 | L87: =SUM(C87:F87)+H87+J87+I87 -> 0.54578231
A88: 45658 | B88: 0.28898404 | C88: 0.21034801 | D88: 0.047373885 | E88: 0.098802824 | F88: 0.10948385 | G88: 0.18102626 | H88: 0.016705719 | I88: 0.01924924 | J88: 0.028026176 | K88: =G88+B88 -> 0.4700103 | L88: =SUM(C88:F88)+H88+J88+I88 -> 0.5299897
A89: 45689 | B89: 0.28075921 | C89: 0.20367688 | D89: 0.046664423 | E89: 0.097478952 | F89: 0.10959804 | G89: 0.18777359 | H89: 0.02678436 | I89: 0.019326865 | J89: 0.027937681 | K89: =G89+B89 -> 0.4685328 | L89: =SUM(C89:F89)+H89+J89+I89 -> 0.5314672
A90: 45717 | B90: 0.28473801 | C90: 0.20423162 | D90: 0.046758764 | E90: 0.096768469 | F90: 0.11248782 | G90: 0.19142075 | H90: 0.015579751 | I90: 0.019924374 | J90: 0.028090444 | K90: =G90+B90 -> 0.47615876 | L90: =SUM(C90:F90)+H90+J90+I90 -> 0.52384124
A91: 45748 | B91: 0.28139064 | C91: 0.20082219 | D91: 0.045669554 | E91: 0.095508046 | F91: 0.11631279 | G91: 0.19313151 | H91: 0.019698765 | I91: 0.019800092 | J91: 0.027666413 | K91: =G91+B91 -> 0.47452215 | L91: =SUM(C91:F91)+H91+J91+I91 -> 0.52547785
A92: 45778 | B92: 0.27849073 | C92: 0.20168847 | D92: 0.046102985 | E92: 0.094388684 | F92: 0.11944456 | G92: 0.19380569 | H92: 0.019044113 | I92: 0.01954698 | J92: 0.027487792 | K92: =G92+B92 -> 0.47229642 | L92: =SUM(C92:F92)+H92+J92+I92 -> 0.52770358
A93: 45809 | B93: 0.27494253 | C93: 0.20667591 | D93: 0.045333372 | E93: 0.092450933 | F93: 0.11818195 | G93: 0.194251 | H93: 0.021579683 | I93: 0.01958633 | J93: 0.02699829 | K93: =G93+B93 -> 0.46919353 | L93: =SUM(C93:F93)+H93+J93+I93 -> 0.53080647
A94: 45839 | B94: 0.27255998 | C94: 0.20598797 | D94: 0.046457692 | E94: 0.092478388 | F94: 0.11930315 | G94: 0.1947126 | H94: 0.021148791 | I94: 0.019890274 | J94: 0.027461157 | K94: =G94+B94 -> 0.46727258 | L94: =SUM(C94:F94)+H94+J94+I94 -> 0.53272742
... A106: 46204 | B106: 0.27246876 | C106: 0.21053213 | D106: 0.050261511 | E106: 0.085399653 | F106: 0.11592057 | G106: 0.19946955 | H106: 0.022122892 | I106: 0.019465522 | J106: 0.024359417 | K106: =G106+B106 -> 0.47193831 | L106: =SUM(C106:F106)+H106+J106+I106 -> 0.52806169
A107: 46235
A108: 46266
A109: 46296
A110: 46327
A111: 46357

Sheet AC
A2: Indicador Serasa Experian de Inadimplência do Consumidor - Acre
A3: Mês | B3: Consumidores Inadimplentes | C3: Dívidas Negativadas | D3: Dívidas Negativadas (R$) | E3: Dívida Média (por CPF) | F3: Dívida Média (R$) | G3: Ticket Médio (R$) | H3: % da População Adulta | I3: % da População Inadimplente
A4: 43466 | B4: 261953 | C4: 1426029 | D4: 8.4928881e+08 | E4: =C4/B4 -> 5.4438353 | F4: =D4/B4 -> 3242.1419 | G4: =F4/E4 -> 595.56209 | H4: 0.47664305 | I4: =(B4/('Consumidores Inadimplentes'!B40*1000000)) -> 0.0042130623
A5: 43497 | B5: 266577 | C5: 1433855 | D5: 8.4868824e+08 | E5: =C5/B5 -> 5.3787649 | F5: =D5/B5 -> 3183.6514 | G5: =F5/E5 -> 591.89265 | H5: 0.4841479 | I5: =(B5/('Consumidores Inadimplentes'!B41*1000000)) -> 0.0042876718
A6: 43525 | B6: 264531 | C6: 1426617 | D6: 8.5961237e+08 | E6: =C6/B6 -> 5.393005 | F6: =D6/B6 -> 3249.5714 | G6: =F6/E6 -> 602.55301 | H6: 0.4795406 | I6: =(B6/('Consumidores Inadimplentes'!B42*1000000)) -> 0.004201567
A7: 43556 | B7: 269472 | C7: 1442902 | D7: 8.8724387e+08 | E7: =C7/B7 -> 5.3545526 | F7: =D7/B7 -> 3292.5271 | G7: =F7/E7 -> 614.90238 | H7: 0.4874688 | I7: =(B7/('Consumidores Inadimplentes'!B43*1000000)) -> 0.0042634329
A8: 43586 | B8: 272325 | C8: 1564438 | D8: 9.0816303e+08 | E8: =C8/B8 -> 5.7447462 | F8: =D8/B8 -> 3334.85 | G8: =F8/E8 -> 580.50433 | H8: 0.4894579 | I8: =(B8/('Consumidores Inadimplentes'!B44*1000000)) -> 0.0042970673
A9: 43617 | B9: 270990 | C9: 1549495 | D9: 9.0617079e+08 | E9: =C9/B9 -> 5.7179047 | F9: =D9/B9 -> 3343.9271 | G9: =F9/E9 -> 584.81686 | H9: 0.48801346 | I9: =(B9/('Consumidores Inadimplentes'!B45*1000000)) -> 0.0042708829
A10: 43647 | B10: 271512 | C10: 1543625 | D10: 9.0657206e+08 | E10: =C10/B10 -> 5.685292 | F10: =D10/B10 -> 3338.976 | G10: =F10/E10 -> 587.30071 | H10: 0.48802387 | I10: =(B10/('Consumidores Inadimplentes'!B46*1000000)) -> 0.0042782476
A11: 43678 | B11: 280278 | C11: 1539642 | D11: 9.1486246e+08 | E11: =C11/B11 -> 5.4932674 | F11: =D11/B11 -> 3264.1251 | G11: =F11/E11 -> 594.20466 | H11: 0.50234614 | I11: =(B11/('Consumidores Inadimplentes'!B47*1000000)) -> 0.0044188414
A12: 43709 | B12: 274824 | C12: 1351233 | D12: 8.8923551e+08 | E12: =C12/B12 -> 4.9167212 | F12: =D12/B12 -> 3235.6545 | G12: =F12/E12 -> 658.09191 | H12: 0.49183743 | I12: =(B12/('Consumidores Inadimplentes'!B48*1000000)) -> 0.0043480263
A13: 43739 | B13: 279325 | C13: 1254619 | D13: 8.9766113e+08 | E13: =C13/B13 -> 4.4916101 | F13: =D13/B13 -> 3213.6799 | G13: =F13/E13 -> 715.48504 | H13: 0.4991485 | I13: =(B13/('Consumidores Inadimplentes'!B49*1000000)) -> 0.0043746097
A14: 43770 | B14: 268771 | C14: 1408000 | D14: 9.2255712e+08 | E14: =C14/B14 -> 5.2386604 | F14: =D14/B14 -> 3432.5025 | G14: =F14/E14 -> 655.22523 | H14: 0.47957398 | I14: =(B14/('Consumidores Inadimplentes'!B50*1000000)) -> 0.0042100082
A15: 43800 | B15: 264469 | C15: 1706203 | D15: 9.5315364e+08 | E15: =C15/B15 -> 6.4514291 | F15: =D15/B15 -> 3604.0278 | G15: =F15/E15 -> 558.64023 | H15: 0.47119578 | I15: =(B15/('Consumidores Inadimplentes'!B51*1000000)) -> 0.0041775407
... A83: 45870 | B83: 288183 | C83: 1057395 | D83: 1549867729 | E83: =C83/B83 -> 3.669179 | F83: =D83/B83 -> 5378.0679 | G83: =F83/E83 -> 1465.7415 | H83: 0.46920288 | I83: =(B83/('Consumidores Inadimplentes'!B119*1000000)) -> 0.0036548792
A84: 45901 | B84: 289737 | C84: 1054592 | D84: 1578510882 | E84: =IFERROR(C84/B84,"") -> 3.6398251 | F84: =IFERROR(D84/B84,"") -> 5448.0818 | G84: =IFERROR(F84/E84,"") -> 1496.7977 | H84: 0.4711707 | I84: =(B84/('Consumidores Inadimplentes'!B120*1000000)) -> 0.0036598226
A85: 45931 | B85: 292004 | C85: 1063736 | D85: 1602600264 | E85: =IFERROR(C85/B85,"") -> 3.6428816 | F85: =IFERROR(D85/B85,"") -> 5488.2819 | G85: =IFERROR(F85/E85,"") -> 1506.5771 | H85: 0.47429117 | I85: =(B85/('Consumidores Inadimplentes'!B121*1000000)) -> 0.003630241
A86: 45962 | B86: 291403 | C86: 1059697 | D86: 1624629714 | E86: =IFERROR(C86/B86,"") -> 3.6365343 | F86: =IFERROR(D86/B86,"") -> 5575.199 | G86: =IFERROR(F86/E86,"") -> 1533.1078 | H86: 0.47275137 | I86: =(B86/('Consumidores Inadimplentes'!B122*1000000)) -> 0.0036149793
A87: 45992 | B87: 293309 | C87: 1060415 | D87: 1642216559 | E87: =IFERROR(C87/B87,"") -> 3.615351 | F87: =IFERROR(D87/B87,"") -> 5598.93 | G87: =IFERROR(F87/E87,"") -> 1548.6546 | H87: 0.4752768 | I87: =(B87/('Consumidores Inadimplentes'!B123*1000000)) -> 0.0036100451
A88: 46023 | B88: 286357 | C88: 1006369 | D88: 1538959090 | E88: =IFERROR(C88/B88,"") -> 3.5143859 | F88: =IFERROR(D88/B88,"") -> 5374.2674 | G88: =IFERROR(F88/E88,"") -> 1529.2195 | H88: 0.46345908 | I88: =(B88/('Consumidores Inadimplentes'!B124*1000000)) -> 0.0035213889
A89: 46054 | B89: 287028 | C89: 1010504 | D89: 1585547407 | E89: =IFERROR(C89/B89,"") -> 3.5205764 | F89: =IFERROR(D89/B89,"") -> 5524.0165 | G89: =IFERROR(F89/E89,"") -> 1569.0659 | H89: 0.46399162 | I89: =(B89/('Consumidores Inadimplentes'!B125*1000000)) -> 0.0035118227
A90: 46082 | B90: 291535 | C90: 1032759 | D90: 1674138352 | E90: =IFERROR(C90/B90,"") -> 3.5424872 | F90: =IFERROR(D90/B90,"") -> 5742.4952 | G90: =IFERROR(F90/E90,"") -> 1621.0349 | H90: 0.47071579 | I90: =(B90/('Consumidores Inadimplentes'!B126*1000000)) -> 0.003519573
A91: 46113 | B91: 296633 | C91: 1050215 | D91: 1708112496 | E91: =IFERROR(C91/B91,"") -> 3.5404523 | F91: =IFERROR(D91/B91,"") -> 5758.336 | G91: =IFERROR(F91/E91,"") -> 1626.4408 | H91: 0.47837628 | I91: =(B91/('Consumidores Inadimplentes'!B127*1000000)) -> 0.0035572116
A92: 46143 | B92: 297943 | C92: 1049861 | D92: 1714931084 | E92: =IFERROR(C92/B92,"") -> 3.5236975 | F92: =IFERROR(D92/B92,"") -> 5755.9033 | G92: =IFERROR(F92/E92,"") -> 1633.4839 | H92: 0.47991618 | I92: =(B92/('Consumidores Inadimplentes'!B128*1000000)) -> 0.003568058
A93: 46174 | B93: 295299 | C93: 1039623 | D93: 1731043484 | E93: =IFERROR(C93/B93,"") -> 3.5205774 | F93: =IFERROR(D93/B93,"") -> 5862.0025 | G93: =IFERROR(F93/E93,"") -> 1665.0685 | H93: 0.47509026 | I93: =(B93/('Consumidores Inadimplentes'!B129*1000000)) -> 0.0035264806
A94: 46204 | B94: 295260 | C94: 1039887 | D94: 1741134395 | E94: =IFERROR(C94/B94,"") -> 3.5219366 | F94: =IFERROR(D94/B94,"") -> 5896.9532 | G94: =IFERROR(F94/E94,"") -> 1674.3496 | H94: 0.47446188 | I94: =(B94/('Consumidores Inadimplentes'!B130*1000000)) -> 0.0035178512
A95: 46235
A96: 46266
A97: 46296
A98: 46327
A99: 46357

Sheet AL
A2: Indicador Serasa Experian de Inadimplência do Consumidor - Alagoas
A3: Mês | B3: Consumidores Inadimplentes | C3: Dívidas Negativadas | D3: Dívidas Negativadas (R$) | E3: Dívida Média (por CPF) | F3: Dívida Média (R$) | G3: Ticket Médio (R$) | H3: % da População Adulta | I3: % da População Inadimplente
A4: 43466 | B4: 957663 | C4: 4016991 | D4: 2.7128861e+09 | E4: =C4/B4 -> 4.1945768 | F4: =D4/B4 -> 2832.8192 | G4: =F4/E4 -> 675.3528 | H4: 0.42645245 | I4: =(B4/('Consumidores Inadimplentes'!B40*1000000)) -> 0.015402358
A5: 43497 | B5: 939283 | C5: 3923638 | D5: 2.6764899e+09 | E5: =C5/B5 -> 4.1772693 | F5: =D5/B5 -> 2849.5032 | G5: =F5/E5 -> 682.14497 | H5: 0.41792986 | I5: =(B5/('Consumidores Inadimplentes'!B41*1000000)) -> 0.015107594
A6: 43525 | B6: 914817 | C6: 3846271 | D6: 2.7376217e+09 | E6: =C6/B6 -> 4.2044157 | F6: =D6/B6 -> 2992.5348 | G6: =F6/E6 -> 711.75995 | H6: 0.40671337 | I6: =(B6/('Consumidores Inadimplentes'!B42*1000000)) -> 0.014530112
A7: 43556 | B7: 897394 | C7: 3729946 | D7: 2.6970165e+09 | E7: =C7/B7 -> 4.1564196 | F7: =D7/B7 -> 3005.3873 | G7: =F7/E7 -> 723.0712 | H7: 0.39829384 | I7: =(B7/('Consumidores Inadimplentes'!B43*1000000)) -> 0.014198058
A8: 43586 | B8: 887668 | C8: 3656722 | D8: 2.7518257e+09 | E8: =C8/B8 -> 4.1194703 | F8: =D8/B8 -> 3100.0619 | G8: =F8/E8 -> 752.53895 | H8: 0.39073763 | I8: =(B8/('Consumidores Inadimplentes'!B44*1000000)) -> 0.01400668
A9: 43617 | B9: 894588 | C9: 3668800 | D9: 2.7631855e+09 | E9: =C9/B9 -> 4.1011058 | F9: =D9/B9 -> 3088.78 | G9: =F9/E9 -> 753.15784 | H9: 0.39698067 | I9: =(B9/('Consumidores Inadimplentes'!B45*1000000)) -> 0.014098973
A10: 43647 | B10: 885537 | C10: 3569137 | D10: 2.7263143e+09 | E10: =C10/B10 -> 4.0304776 | F10: =D10/B10 -> 3078.713 | G10: =F10/E10 -> 763.85812 | H10: 0.39241289 | I10: =(B10/('Consumidores Inadimplentes'!B46*1000000)) -> 0.013953514
A11: 43678 | B11: 884630 | C11: 3538047 | D11: 2.8015816e+09 | E11: =C11/B11 -> 3.9994653 | F11: =D11/B11 -> 3166.953 | G11: =F11/E11 -> 791.8441 | H11: 0.38969472 | I11: =(B11/('Consumidores Inadimplentes'!B47*1000000)) -> 0.013947008
A12: 43709 | B12: 872746 | C12: 3438933 | D12: 2.7603464e+09 | E12: =C12/B12 -> 3.9403595 | F12: =D12/B12 -> 3162.829 | G12: =F12/E12 -> 802.67524 | H12: 0.38416988 | I12: =(B12/('Consumidores Inadimplentes'!B48*1000000)) -> 0.013807828
A13: 43739 | B13: 872843 | C13: 3891440 | D13: 2.8008505e+09 | E13: =C13/B13 -> 4.4583505 | F13: =D13/B13 -> 3208.8823 | G13: =F13/E13 -> 719.74654 | H13: 0.38392309 | I13: =(B13/('Consumidores Inadimplentes'!B49*1000000)) -> 0.01366991
A14: 43770 | B14: 862443 | C14: 3855787 | D14: 2.7867637e+09 | E14: =C14/B14 -> 4.4707731 | F14: =D14/B14 -> 3231.2439 | G14: =F14/E14 -> 722.74836 | H14: 0.37906267 | I14: =(B14/('Consumidores Inadimplentes'!B50*1000000)) -> 0.013509241
A15: 43800 | B15: 857101 | C15: 3789441 | D15: 2.7696306e+09 | E15: =C15/B15 -> 4.4212304 | F15: =D15/B15 -> 3231.3935 | G15: =F15/E15 -> 730.88104 | H15: 0.37643083 | I15: =(B15/('Consumidores Inadimplentes'!B51*1000000)) -> 0.01353873
... A83: 45870 | B83: 1102371 | C83: 3192409 | D83: 5514525061 | E83: =C83/B83 -> 2.8959479 | F83: =D83/B83 -> 5002.4221 | G83: =F83/E83 -> 1727.3868 | H83: 0.46614621 | I83: =(B83/('Consumidores Inadimplentes'!B119*1000000)) -> 0.013980814
A84: 45901 | B84: 1099312 | C84: 3156608 | D84: 5481283861 | E84: =IFERROR(C84/B84,"") -> 2.8714396 | F84: =IFERROR(D84/B84,"") -> 4986.1039 | G84: =IFERROR(F84/E84,"") -> 1736.4474 | H84: 0.46461732 | I84: =(B84/('Consumidores Inadimplentes'!B120*1000000)) -> 0.013885996
A85: 45931 | B85: 1113986 | C85: 3229198 | D85: 5576686003 | E85: =IFERROR(C85/B85,"") -> 2.8987779 | F85: =IFERROR(D85/B85,"") -> 5006.0647 | G85: =IFERROR(F85/E85,"") -> 1726.957 | H85: 0.47058073 | I85: =(B85/('Consumidores Inadimplentes'!B121*1000000)) -> 0.013849254
A86: 45962 | B86: 1106631 | C86: 3167430 | D86: 5467426731 | E86: =IFERROR(C86/B86,"") -> 2.8622278 | F86: =IFERROR(D86/B86,"") -> 4940.6051 | G86: =IFERROR(F86/E86,"") -> 1726.1397 | H86: 0.46723711 | I86: =(B86/('Consumidores Inadimplentes'!B122*1000000)) -> 0.013728233
A87: 45992 | B87: 1114686 | C87: 3197530 | D87: 5559906197 | E87: =IFERROR(C87/B87,"") -> 2.8685477 | F87: =IFERROR(D87/B87,"") -> 4987.8676 | G87: =IFERROR(F87/E87,"") -> 1738.8128 | H87: 0.47039972 | I87: =(B87/('Consumidores Inadimplentes'!B123*1000000)) -> 0.013719547
A88: 46023 | B88: 1097072 | C88: 3137596 | D88: 5546694900 | E88: =IFERROR(C88/B88,"") -> 2.8599727 | F88: =IFERROR(D88/B88,"") -> 5055.9078 | G88: =IFERROR(F88/E88,"") -> 1767.8168 | H88: 0.46273225 | I88: =(B88/('Consumidores Inadimplentes'!B124*1000000)) -> 0.013490912
A89: 46054 | B89: 1108663 | C89: 3218938 | D89: 5732958286 | E89: =IFERROR(C89/B89,"") -> 2.9034414 | F89: =IFERROR(D89/B89,"") -> 5171.0558 | G89: =IFERROR(F89/E89,"") -> 1781.0092 | H89: 0.46738444 | I89: =(B89/('Consumidores Inadimplentes'!B125*1000000)) -> 0.013564628
A90: 46082 | B90: 1119006 | C90: 3309398 | D90: 5990129810 | E90: =IFERROR(C90/B90,"") -> 2.9574444 | F90: =IFERROR(D90/B90,"") -> 5353.081 | G90: =IFERROR(F90/E90,"") -> 1810.0361 | H90: 0.47150586 | I90: =(B90/('Consumidores Inadimplentes'!B126*1000000)) -> 0.013509264
A91: 46113 | B91: 1134220 | C91: 3368795 | D91: 6057611486 | E91: =IFERROR(C91/B91,"") -> 2.9701425 | F91: =IFERROR(D91/B91,"") -> 5340.7729 | G91: =IFERROR(F91/E91,"") -> 1798.1538 | H91: 0.47767452 | I91: =(B91/('Consumidores Inadimplentes'!B127*1000000)) -> 0.013601523
A92: 46143 | B92: 1130131 | C92: 3353035 | D92: 6058204964 | E92: =IFERROR(C92/B92,"") -> 2.9669437 | F92: =IFERROR(D92/B92,"") -> 5360.6219 | G92: =IFERROR(F92/E92,"") -> 1806.7825 | H92: 0.47571143 | I92: =(B92/('Consumidores Inadimplentes'!B128*1000000)) -> 0.013534042
A93: 46174 | B93: 1130030 | C93: 3358087 | D93: 6083310299 | E93: =IFERROR(C93/B93,"") -> 2.9716795 | F93: =IFERROR(D93/B93,"") -> 5383.3175 | G93: =IFERROR(F93/E93,"") -> 1811.5404 | H93: 0.47542817 | I93: =(B93/('Consumidores Inadimplentes'!B129*1000000)) -> 0.013494895
A94: 46204 | B94: 1137673 | C94: 3405326 | D94: 6162368800 | E94: =IFERROR(C94/B94,"") -> 2.993238 | F94: =IFERROR(D94/B94,"") -> 5416.6433 | G94: =IFERROR(F94/E94,"") -> 1809.6267 | H94: 0.47840121 | I94: =(B94/('Consumidores Inadimplentes'!B130*1000000)) -> 0.013554712
A95: 46235
A96: 46266
A97: 46296
A98: 46327
A99: 46357

Sheet AM
A2: Indicador Serasa Experian de Inadimplência do Consumidor - Amazonas
A3: Mês | B3: Consumidores Inadimplentes | C3: Dívidas Negativadas | D3: Dívidas Negativadas (R$) | E3: Dívida Média (por CPF) | F3: Dívida Média (R$) | G3: Ticket Médio (R$) | H3: % da População Adulta | I3: % da População Inadimplente
A4: 43466 | B4: 1311643 | C4: 4314306 | D4: 4.218828e+09 | E4: =C4/B4 -> 3.289238 | F4: =D4/B4 -> 3216.4453 | G4: =F4/E4 -> 977.86944 | H4: 0.50089 | I4: =(B4/('Consumidores Inadimplentes'!B40*1000000)) -> 0.021095516
A5: 43497 | B5: 1317052 | C5: 4343199 | D5: 4.2069573e+09 | E5: =C5/B5 -> 3.2976671 | F5: =D5/B5 -> 3194.2226 | G5: =F5/E5 -> 968.63103 | H5: 0.50194741 | I5: =(B5/('Consumidores Inadimplentes'!B41*1000000)) -> 0.021183698
A6: 43525 | B6: 1335918 | C6: 4447182 | D6: 4.2876482e+09 | E6: =C6/B6 -> 3.3289334 | F6: =D6/B6 -> 3209.5145 | G6: =F6/E6 -> 964.12699 | H6: 0.50805479 | I6: =(B6/('Consumidores Inadimplentes'!B42*1000000)) -> 0.021218492
A7: 43556 | B7: 1339201 | C7: 4482756 | D7: 4.3826172e+09 | E7: =C7/B7 -> 3.3473362 | F7: =D7/B7 -> 3272.5612 | G7: =F7/E7 -> 977.66133 | H7: 0.5081 | I7: =(B7/('Consumidores Inadimplentes'!B43*1000000)) -> 0.021188078
A8: 43586 | B8: 1352166 | C8: 4559707 | D8: 4.4108136e+09 | E8: =C8/B8 -> 3.3721503 | F8: =D8/B8 -> 3262.0356 | G8: =F8/E8 -> 967.34585 | H8: 0.50801827 | I8: =(B8/('Consumidores Inadimplentes'!B44*1000000)) -> 0.021336081
A9: 43617 | B9: 1381690 | C9: 4680307 | D9: 4.5760299e+09 | E9: =C9/B9 -> 3.3873785 | F9: =D9/B9 -> 3311.9078 | G9: =F9/E9 -> 977.72002 | H9: 0.52081789 | I9: =(B9/('Consumidores Inadimplentes'!B45*1000000)) -> 0.021775845
A10: 43647 | B10: 1456846 | C10: 5053043 | D10: 5.1936999e+09 | E10: =C10/B10 -> 3.4684812 | F10: =D10/B10 -> 3565.0302 | G10: =F10/E10 -> 1027.8361 | H10: 0.54548328 | I10: =(B10/('Consumidores Inadimplentes'!B46*1000000)) -> 0.022955699
A11: 43678 | B11: 1454265 | C11: 5071979 | D11: 5.2184101e+09 | E11: =C11/B11 -> 3.487658 | F11: =D11/B11 -> 3588.3488 | G11: =F11/E11 -> 1028.8706 | H11: 0.54635159 | I11: =(B11/('Consumidores Inadimplentes'!B47*1000000)) -> 0.02292783
A12: 43709 | B12: 1456620 | C12: 5094800 | D12: 5.1676508e+09 | E12: =C12/B12 -> 3.4976864 | F12: =D12/B12 -> 3547.7 | G12: =F12/E12 -> 1014.299 | H12: 0.54620029 | I12: =(B12/('Consumidores Inadimplentes'!B48*1000000)) -> 0.023045375
A13: 43739 | B13: 1464975 | C13: 5149157 | D13: 5.1612219e+09 | E13: =C13/B13 -> 3.5148429 | F13: =D13/B13 -> 3523.0785 | G13: =F13/E13 -> 1002.3431 | H13: 0.54856061 | I13: =(B13/('Consumidores Inadimplentes'!B49*1000000)) -> 0.022943503
A14: 43770 | B14: 1506878 | C14: 5420895 | D14: 5.2988619e+09 | E14: =C14/B14 -> 3.5974346 | F14: =D14/B14 -> 3516.4505 | G14: =F14/E14 -> 977.48838 | H14: 0.56332014 | I14: =(B14/('Consumidores Inadimplentes'!B50*1000000)) -> 0.023603621
A15: 43800 | B15: 1486921 | C15: 5339362 | D15: 5.2557185e+09 | E15: =C15/B15 -> 3.5908848 | F15: =D15/B15 -> 3534.632 | G15: =F15/E15 -> 984.33456 | H15: 0.5549424 | I15: =(B15/('Consumidores Inadimplentes'!B51*1000000)) -> 0.023487339
... A83: 45870 | B83: 1687120 | C83: 7378162 | D83: 9216159057 | E83: =C83/B83 -> 4.3732289 | F83: =D83/B83 -> 5462.6577 | G83: =F83/E83 -> 1249.1131 | H83: 0.56915635 | I83: =(B83/('Consumidores Inadimplentes'!B119*1000000)) -> 0.02139689
A84: 45901 | B84: 1701290 | C84: 7378248 | D84: 9323631874 | E84: =IFERROR(C84/B84,"") -> 4.336855 | F84: =IFERROR(D84/B84,"") -> 5480.3307 | G84: =IFERROR(F84/E84,"") -> 1263.6647 | H84: 0.57306765 | I84: =(B84/('Consumidores Inadimplentes'!B120*1000000)) -> 0.021489901
A85: 45931 | B85: 1726646 | C85: 7502711 | D85: 9551943201 | E85: =IFERROR(C85/B85,"") -> 4.3452514 | F85: =IFERROR(D85/B85,"") -> 5532.0797 | G85: =IFERROR(F85/E85,"") -> 1273.1322 | H85: 0.58072799 | I85: =(B85/('Consumidores Inadimplentes'!B121*1000000)) -> 0.021465943
A86: 45962 | B86: 1732294 | C86: 7513417 | D86: 9714480877 | E86: =IFERROR(C86/B86,"") -> 4.3372643 | F86: =IFERROR(D86/B86,"") -> 5607.8708 | G86: =IFERROR(F86/E86,"") -> 1292.9511 | H86: 0.58174536 | I86: =(B86/('Consumidores Inadimplentes'!B122*1000000)) -> 0.021489851
A87: 45992 | B87: 1737276 | C87: 7566331 | D87: 9714187433 | E87: =IFERROR(C87/B87,"") -> 4.3552844 | F87: =IFERROR(D87/B87,"") -> 5591.6201 | G87: =IFERROR(F87/E87,"") -> 1283.8703 | H87: 0.58253517 | I87: =(B87/('Consumidores Inadimplentes'!B123*1000000)) -> 0.021382381
A88: 46023 | B88: 1751815 | C88: 7623080 | D88: 9915039652 | E88: =IFERROR(C88/B88,"") -> 4.3515326 | F88: =IFERROR(D88/B88,"") -> 5659.8669 | G88: =IFERROR(F88/E88,"") -> 1300.6606 | H88: 0.58652098 | I88: =(B88/('Consumidores Inadimplentes'!B124*1000000)) -> 0.021542417
A89: 46054 | B89: 1759071 | C89: 7699952 | D89: 10175598694 | E89: =IFERROR(C89/B89,"") -> 4.3772832 | F89: =IFERROR(D89/B89,"") -> 5784.6435 | G89: =IFERROR(F89/E89,"") -> 1321.5146 | H89: 0.58805865 | I89: =(B89/('Consumidores Inadimplentes'!B125*1000000)) -> 0.021522449
A90: 46082 | B90: 1800624 | C90: 7934041 | D90: 10562602643 | E90: =IFERROR(C90/B90,"") -> 4.406273 | F90: =IFERROR(D90/B90,"") -> 5866.079 | G90: =IFERROR(F90/E90,"") -> 1331.3017 | H90: 0.60103843 | I90: =(B90/('Consumidores Inadimplentes'!B126*1000000)) -> 0.021738137
A91: 46113 | B91: 1815169 | C91: 8032857 | D91: 10832802057 | E91: =IFERROR(C91/B91,"") -> 4.4254045 | F91: =IFERROR(D91/B91,"") -> 5967.9303 | G91: =IFERROR(F91/E91,"") -> 1348.5615 | H91: 0.60497607 | I91: =(B91/('Consumidores Inadimplentes'!B127*1000000)) -> 0.021767437
A92: 46143 | B92: 1814950 | C92: 8033395 | D92: 10994817989 | E92: =IFERROR(C92/B92,"") -> 4.4262349 | F92: =IFERROR(D92/B92,"") -> 6057.9178 | G92: =IFERROR(F92/E92,"") -> 1368.639 | H92: 0.60398716 | I92: =(B92/('Consumidores Inadimplentes'!B128*1000000)) -> 0.021735187
A93: 46174 | B93: 1812345 | C93: 8022582 | D93: 11099523387 | E93: =IFERROR(C93/B93,"") -> 4.4266307 | F93: =IFERROR(D93/B93,"") -> 6124.3987 | G93: =IFERROR(F93/E93,"") -> 1383.535 | H93: 0.60220701 | I93: =(B93/('Consumidores Inadimplentes'!B129*1000000)) -> 0.021643147
A94: 46204 | B94: 1831625 | C94: 8149691 | D94: 11287585886 | E94: =IFERROR(C94/B94,"") -> 4.4494321 | F94: =IFERROR(D94/B94,"") -> 6162.6075 | G94: =IFERROR(F94/E94,"") -> 1385.0324 | H94: 0.60769179 | I94: =(B94/('Consumidores Inadimplentes'!B130*1000000)) -> 0.021822747
A95: 46235
A96: 46266
A97: 46296
A98: 46327
A99: 46357

Sheet AP
A2: Indicador Serasa Experian de Inadimplência do Consumidor - Amapá
A3: Mês | B3: Consumidores Inadimplentes | C3: Dívidas Negativadas | D3: Dívidas Negativadas (R$) | E3: Dívida Média (por CPF) | F3: Dívida Média (R$) | G3: Ticket Médio (R$) | H3: % da População Adulta | I3: % da População Inadimplente
A4: 43466 | B4: 269548 | C4: 1116041 | D4: 1.0512039e+09 | E4: =C4/B4 -> 4.1404165 | F4: =D4/B4 -> 3899.8765 | G4: =F4/E4 -> 941.9044 | H4: 0.53976523 | I4: =(B4/('Consumidores Inadimplentes'!B40*1000000)) -> 0.0043352148
A5: 43497 | B5: 269239 | C5: 1134180 | D5: 1.0409792e+09 | E5: =C5/B5 -> 4.2125398 | F5: =D5/B5 -> 3866.376 | G5: =F5/E5 -> 917.82541 | H5: 0.53823288 | I5: =(B5/('Consumidores Inadimplentes'!B41*1000000)) -> 0.0043304878
A6: 43525 | B6: 270498 | C6: 1175882 | D6: 1.0722074e+09 | E6: =C6/B6 -> 4.3471005 | F6: =D6/B6 -> 3963.8274 | G6: =F6/E6 -> 911.83247 | H6: 0.5397518 | I6: =(B6/('Consumidores Inadimplentes'!B42*1000000)) -> 0.0042963414
A7: 43556 | B7: 271852 | C7: 1203775 | D7: 1.0821325e+09 | E7: =C7/B7 -> 4.4280528 | F7: =D7/B7 -> 3980.5941 | G7: =F7/E7 -> 898.94911 | H7: 0.54138433 | I7: =(B7/('Consumidores Inadimplentes'!B43*1000000)) -> 0.0043010879
A8: 43586 | B8: 272756 | C8: 1200510 | D8: 1.0916523e+09 | E8: =C8/B8 -> 4.4014064 | F8: =D8/B8 -> 4002.3033 | G8: =F8/E8 -> 909.32375 | H8: 0.53929556 | I8: =(B8/('Consumidores Inadimplentes'!B44*1000000)) -> 0.0043038681
A9: 43617 | B9: 273961 | C9: 1194670 | D9: 1.0921862e+09 | E9: =C9/B9 -> 4.3607302 | F9: =D9/B9 -> 3986.6485 | G9: =F9/E9 -> 914.21582 | H9: 0.54333739 | I9: =(B9/('Consumidores Inadimplentes'!B45*1000000)) -> 0.0043177067
A10: 43647 | B10: 271423 | C10: 1179862 | D10: 1.0876299e+09 | E10: =C10/B10 -> 4.3469492 | F10: =D10/B10 -> 4007.1396 | G10: =F10/E10 -> 921.82803 | H10: 0.5371005 | I10: =(B10/('Consumidores Inadimplentes'!B46*1000000)) -> 0.0042768452
A11: 43678 | B11: 273740 | C11: 1183483 | D11: 1.095967e+09 | E11: =C11/B11 -> 4.3233835 | F11: =D11/B11 -> 4003.6786 | G11: =F11/E11 -> 926.05215 | H11: 0.54087804 | I11: =(B11/('Consumidores Inadimplentes'!B47*1000000)) -> 0.0043157638
A12: 43709 | B12: 272345 | C12: 1185109 | D12: 1.078053e+09 | E12: =C12/B12 -> 4.351499 | F12: =D12/B12 -> 3958.4095 | G12: =F12/E12 -> 909.66572 | H12: 0.53735722 | I12: =(B12/('Consumidores Inadimplentes'!B48*1000000)) -> 0.0043088057
A13: 43739 | B13: 275380 | C13: 1184658 | D13: 1.0771021e+09 | E13: =C13/B13 -> 4.3019028 | F13: =D13/B13 -> 3911.3301 | G13: =F13/E13 -> 909.20931 | H13: 0.54257365 | I13: =(B13/('Consumidores Inadimplentes'!B49*1000000)) -> 0.0043128257
A14: 43770 | B14: 273541 | C14: 1192241 | D14: 1.077671e+09 | E14: =C14/B14 -> 4.3585459 | F14: =D14/B14 -> 3939.7055 | G14: =F14/E14 -> 903.90364 | H14: 0.53818473 | I14: =(B14/('Consumidores Inadimplentes'!B50*1000000)) -> 0.0042847251
A15: 43800 | B15: 272721 | C15: 1177641 | D15: 1.0619659e+09 | E15: =C15/B15 -> 4.3181163 | F15: =D15/B15 -> 3893.9644 | G15: =F15/E15 -> 901.77386 | H15: 0.53580922 | I15: =(B15/('Consumidores Inadimplentes'!B51*1000000)) -> 0.0043078889
... A83: 45870 | B83: 356905 | C83: 1539095 | D83: 1912587369 | E83: =C83/B83 -> 4.312338 | F83: =D83/B83 -> 5358.8136 | G83: =F83/E83 -> 1242.6701 | H83: 0.64624274 | I83: =(B83/('Consumidores Inadimplentes'!B119*1000000)) -> 0.0045264456
A84: 45901 | B84: 355848 | C84: 1507045 | D84: 1935647610 | E84: =IFERROR(C84/B84,"") -> 4.2350807 | F84: =IFERROR(D84/B84,"") -> 5439.5349 | G84: =IFERROR(F84/E84,"") -> 1284.3993 | H84: 0.6436261 | I84: =(B84/('Consumidores Inadimplentes'!B120*1000000)) -> 0.0044949059
A85: 45931 | B85: 362516 | C85: 1535015 | D85: 1998837014 | E85: =IFERROR(C85/B85,"") -> 4.2343372 | F85: =IFERROR(D85/B85,"") -> 5513.7898 | G85: =IFERROR(F85/E85,"") -> 1302.1612 | H85: 0.65497106 | I85: =(B85/('Consumidores Inadimplentes'!B121*1000000)) -> 0.0045068577
A86: 45962 | B86: 361262 | C86: 1498734 | D86: 2032514356 | E86: =IFERROR(C86/B86,"") -> 4.1486068 | F86: =IFERROR(D86/B86,"") -> 5626.1504 | G86: =IFERROR(F86/E86,"") -> 1356.1542 | H86: 0.65199273 | I86: =(B86/('Consumidores Inadimplentes'!B122*1000000)) -> 0.0044816102
A87: 45992 | B87: 366222 | C87: 1493283 | D87: 2086155204 | E87: =IFERROR(C87/B87,"") -> 4.0775349 | F87: =IFERROR(D87/B87,"") -> 5696.4224 | G87: =IFERROR(F87/E87,"") -> 1397.026 | H87: 0.66022347 | I87: =(B87/('Consumidores Inadimplentes'!B123*1000000)) -> 0.0045074578
A88: 46023 | B88: 354990 | C88: 1396176 | D88: 1881937728 | E88: =IFERROR(C88/B88,"") -> 3.9330009 | F88: =IFERROR(D88/B88,"") -> 5301.3824 | G88: =IFERROR(F88/E88,"") -> 1347.923 | H88: 0.63927607 | I88: =(B88/('Consumidores Inadimplentes'!B124*1000000)) -> 0.0043653826
A89: 46054 | B89: 357306 | C89: 1392072 | D89: 1949371011 | E89: =IFERROR(C89/B89,"") -> 3.8960219 | F89: =IFERROR(D89/B89,"") -> 5455.7466 | G89: =IFERROR(F89/E89,"") -> 1400.3378 | H89: 0.6427442 | I89: =(B89/('Consumidores Inadimplentes'!B125*1000000)) -> 0.0043716827
A90: 46082 | B90: 362350 | C90: 1400017 | D90: 2052942059 | E90: =IFERROR(C90/B90,"") -> 3.8637146 | F90: =IFERROR(D90/B90,"") -> 5665.6328 | G90: =IFERROR(F90/E90,"") -> 1466.3694 | H90: 0.65110671 | I90: =(B90/('Consumidores Inadimplentes'!B126*1000000)) -> 0.0043744912
A91: 46113 | B91: 365598 | C91: 1396887 | D91: 2069178238 | E91: =IFERROR(C91/B91,"") -> 3.8208278 | F91: =IFERROR(D91/B91,"") -> 5659.7089 | G91: =IFERROR(F91/E91,"") -> 1481.2782 | H91: 0.6562261 | I91: =(B91/('Consumidores Inadimplentes'!B127*1000000)) -> 0.0043842372
A92: 46143 | B92: 363407 | C92: 1359718 | D92: 2051593735 | E92: =IFERROR(C92/B92,"") -> 3.7415845 | F92: =IFERROR(D92/B92,"") -> 5645.4436 | G92: =IFERROR(F92/E92,"") -> 1508.8377 | H92: 0.65158114 | I92: =(B92/('Consumidores Inadimplentes'!B128*1000000)) -> 0.0043520313
A93: 46174 | B93: 363606 | C93: 1335692 | D93: 2074133837 | E93: =IFERROR(C93/B93,"") -> 3.6734597 | F93: =IFERROR(D93/B93,"") -> 5704.3444 | G93: =IFERROR(F93/E93,"") -> 1552.8534 | H93: 0.65122685 | I93: =(B93/('Consumidores Inadimplentes'!B129*1000000)) -> 0.0043422074
A94: 46204 | B94: 362541 | C94: 1315232 | D94: 2089119501 | E94: =IFERROR(C94/B94,"") -> 3.6278159 | F94: =IFERROR(D94/B94,"") -> 5762.4365 | G94: =IFERROR(F94/E94,"") -> 1588.4038 | H94: 0.64861079 | I94: =(B94/('Consumidores Inadimplentes'!B130*1000000)) -> 0.0043194652
A95: 46235
A96: 46266
A97: 46296
A98: 46327
A99: 46357

Sheet BA
A2: Indicador Serasa Experian de Inadimplência do Consumidor - Bahia
A3: Mês | B3: Consumidores Inadimplentes | C3: Dívidas Negativadas | D3: Dívidas Negativadas (R$) | E3: Dívida Média (por CPF) | F3: Dívida Média (R$) | G3: Ticket Médio (R$) | H3: % da População Adulta | I3: % da População Inadimplente
A4: 43466 | B4: 3982920 | C4: 13242724 | D4: 1.0036048e+10 | E4: =C4/B4 -> 3.3248782 | F4: =D4/B4 -> 2519.7714 | G4: =F4/E4 -> 757.85375 | H4: 0.37123185 | I4: =(B4/('Consumidores Inadimplentes'!B40*1000000)) -> 0.0640584
A5: 43497 | B5: 3958677 | C5: 13092028 | D5: 1.0008016e+10 | E5: =C5/B5 -> 3.3071726 | F5: =D5/B5 -> 2528.1214 | G5: =F5/E5 -> 764.43588 | H5: 0.36857522 | I5: =(B5/('Consumidores Inadimplentes'!B41*1000000)) -> 0.063672063
A6: 43525 | B6: 3997409 | C6: 13214788 | D6: 1.0356342e+10 | E6: =C6/B6 -> 3.3058384 | F6: =D6/B6 -> 2590.7637 | G6: =F6/E6 -> 783.69341 | H6: 0.37168371 | I6: =(B6/('Consumidores Inadimplentes'!B42*1000000)) -> 0.063491167
A7: 43556 | B7: 4057562 | C7: 13238374 | D7: 1.0318723e+10 | E7: =C7/B7 -> 3.2626424 | F7: =D7/B7 -> 2543.0844 | G7: =F7/E7 -> 779.45544 | H7: 0.37660786 | I7: =(B7/('Consumidores Inadimplentes'!B43*1000000)) -> 0.064196441
A8: 43586 | B8: 4073306 | C8: 13209493 | D8: 1.0584385e+10 | E8: =C8/B8 -> 3.2429415 | F8: =D8/B8 -> 2598.4754 | G8: =F8/E8 -> 801.27112 | H8: 0.37517322 | I8: =(B8/('Consumidores Inadimplentes'!B44*1000000)) -> 0.064273459
A9: 43617 | B9: 4086651 | C9: 13120269 | D9: 1.0624394e+10 | E9: =C9/B9 -> 3.2105186 | F9: =D9/B9 -> 2599.7801 | G9: =F9/E9 -> 809.76953 | H9: 0.3775631 | I9: =(B9/('Consumidores Inadimplentes'!B45*1000000)) -> 0.064406833
A10: 43647 | B10: 4046120 | C10: 12964607 | D10: 1.0621966e+10 | E10: =C10/B10 -> 3.2042072 | F10: =D10/B10 -> 2625.2227 | G10: =F10/E10 -> 819.3049 | H10: 0.37172255 | I10: =(B10/('Consumidores Inadimplentes'!B46*1000000)) -> 0.063755204
A11: 43678 | B11: 4016549 | C11: 12882357 | D11: 1.0729448e+10 | E11: =C11/B11 -> 3.2073198 | F11: =D11/B11 -> 2671.3102 | G11: =F11/E11 -> 832.8793 | H11: 0.36992312 | I11: =(B11/('Consumidores Inadimplentes'!B47*1000000)) -> 0.063324602
A12: 43709 | B12: 3966676 | C12: 12597163 | D12: 1.0515063e+10 | E12: =C12/B12 -> 3.1757479 | F12: =D12/B12 -> 2650.8501 | G12: =F12/E12 -> 834.71678 | H12: 0.36778065 | I12: =(B12/('Consumidores Inadimplentes'!B48*1000000)) -> 0.062757298
A13: 43739 | B13: 4009454 | C13: 12718545 | D13: 1.0699057e+10 | E13: =C13/B13 -> 3.1721389 | F13: =D13/B13 -> 2668.4574 | G13: =F13/E13 -> 841.21707 | H13: 0.36864363 | I13: =(B13/('Consumidores Inadimplentes'!B49*1000000)) -> 0.062793508
A14: 43770 | B14: 4030634 | C14: 12652731 | D14: 1.0848012e+10 | E14: =C14/B14 -> 3.1391416 | F14: =D14/B14 -> 2691.3909 | G14: =F14/E14 -> 857.36523 | H14: 0.37027673 | I14: =(B14/('Consumidores Inadimplentes'!B50*1000000)) -> 0.06313554
A15: 43800 | B15: 3951191 | C15: 12395578 | D15: 1.0851225e+10 | E15: =C15/B15 -> 3.1371751 | F15: =D15/B15 -> 2746.3174 | G15: =F15/E15 -> 875.41095 | H15: 0.36267083 | I15: =(B15/('Consumidores Inadimplentes'!B51*1000000)) -> 0.062412839
... A83: 45870 | B83: 4949309 | C83: 14765495 | D83: 22136545939 | E83: =C83/B83 -> 2.9833447 | F83: =D83/B83 -> 4472.6538 | G83: =F83/E83 -> 1499.2078 | H83: 0.43425493 | I83: =(B83/('Consumidores Inadimplentes'!B119*1000000)) -> 0.062769583
A84: 45901 | B84: 4967399 | C84: 14714387 | D84: 22356785437 | E84: =IFERROR(C84/B84,"") -> 2.9621915 | F84: =IFERROR(D84/B84,"") -> 4500.7026 | G84: =IFERROR(F84/E84,"") -> 1519.3827 | H84: 0.43558506 | I84: =(B84/('Consumidores Inadimplentes'!B120*1000000)) -> 0.062745866
A85: 45931 | B85: 5046908 | C85: 15057910 | D85: 22768083836 | E85: =IFERROR(C85/B85,"") -> 2.9835911 | F85: =IFERROR(D85/B85,"") -> 4511.2936 | G85: =IFERROR(F85/E85,"") -> 1512.0348 | H85: 0.44229605 | I85: =(B85/('Consumidores Inadimplentes'!B121*1000000)) -> 0.062743978
A86: 45962 | B86: 5020140 | C86: 14805866 | D86: 22132013092 | E86: =IFERROR(C86/B86,"") -> 2.9492934 | F86: =IFERROR(D86/B86,"") -> 4408.6446 | G86: =IFERROR(F86/E86,"") -> 1494.8138 | H86: 0.43969066 | I86: =(B86/('Consumidores Inadimplentes'!B122*1000000)) -> 0.062276992
A87: 45992 | B87: 5034497 | C87: 14765842 | D87: 21962567229 | E87: =IFERROR(C87/B87,"") -> 2.9329329 | F87: =IFERROR(D87/B87,"") -> 4362.4154 | G87: =IFERROR(F87/E87,"") -> 1487.3901 | H87: 0.44068801 | I87: =(B87/('Consumidores Inadimplentes'!B123*1000000)) -> 0.061964553
A88: 46023 | B88: 4972121 | C88: 14345402 | D88: 20872160639 | E88: =IFERROR(C88/B88,"") -> 2.8851675 | F88: =IFERROR(D88/B88,"") -> 4197.8384 | G88: =IFERROR(F88/E88,"") -> 1454.9722 | H88: 0.43497128 | I88: =(B88/('Consumidores Inadimplentes'!B124*1000000)) -> 0.06114316
A89: 46054 | B89: 4987714 | C89: 14508775 | D89: 21448409502 | E89: =IFERROR(C89/B89,"") -> 2.9089028 | F89: =IFERROR(D89/B89,"") -> 4300.2485 | G89: =IFERROR(F89/E89,"") -> 1478.306 | H89: 0.43607799 | I89: =(B89/('Consumidores Inadimplentes'!B125*1000000)) -> 0.061025292
A90: 46082 | B90: 5047365 | C90: 14823251 | D90: 22106301793 | E90: =IFERROR(C90/B90,"") -> 2.9368296 | F90: =IFERROR(D90/B90,"") -> 4379.7708 | G90: =IFERROR(F90/E90,"") -> 1491.3261 | H90: 0.44103299 | I90: =(B90/('Consumidores Inadimplentes'!B126*1000000)) -> 0.060934604
A91: 46113 | B91: 5117754 | C91: 15221666 | D91: 22815944944 | E91: =IFERROR(C91/B91,"") -> 2.9742864 | F91: =IFERROR(D91/B91,"") -> 4458.1949 | G91: =IFERROR(F91/E91,"") -> 1498.9125 | H91: 0.44691971 | I91: =(B91/('Consumidores Inadimplentes'!B127*1000000)) -> 0.06137191
A92: 46143 | B92: 5179426 | C92: 15493753 | D92: 23186532825 | E92: =IFERROR(C92/B92,"") -> 2.9914035 | F92: =IFERROR(D92/B92,"") -> 4476.6607 | G92: =IFERROR(F92/E92,"") -> 1496.5085 | H92: 0.45203854 | I92: =(B92/('Consumidores Inadimplentes'!B128*1000000)) -> 0.06202694
A93: 46174 | B93: 5194983 | C93: 15551695 | D93: 23279304598 | E93: =IFERROR(C93/B93,"") -> 2.9935988 | F93: =IFERROR(D93/B93,"") -> 4481.1128 | G93: =IFERROR(F93/E93,"") -> 1496.8982 | H93: 0.45312884 | I93: =(B93/('Consumidores Inadimplentes'!B129*1000000)) -> 0.062038838
A94: 46204 | B94: 5239780 | C94: 15823095 | D94: 23833575376 | E94: =IFERROR(C94/B94,"") -> 3.0198014 | F94: =IFERROR(D94/B94,"") -> 4548.5832 | G94: =IFERROR(F94/E94,"") -> 1506.2524 | H94: 0.45676666 | I94: =(B94/('Consumidores Inadimplentes'!B130*1000000)) -> 0.062428932
A95: 46235
A96: 46266
A97: 46296
A98: 46327
A99: 46357

Sheet CE
A2: Indicador Serasa Experian de Inadimplência do Consumidor - Ceará
A3: Mês | B3: Consumidores Inadimplentes | C3: Dívidas Negativadas | D3: Dívidas Negativadas (R$) | E3: Dívida Média (por CPF) | F3: Dívida Média (R$) | G3: Ticket Médio (R$) | H3: % da População Adulta | I3: % da População Inadimplente
A4: 43466 | B4: 2428671 | C4: 7984109 | D4: 7.3772514e+09 | E4: =C4/B4 -> 3.2874395 | F4: =D4/B4 -> 3037.5672 | G4: =F4/E4 -> 923.99182 | H4: 0.37066882 | I4: =(B4/('Consumidores Inadimplentes'!B40*1000000)) -> 0.039060985
A5: 43497 | B5: 2428001 | C5: 8005727 | D5: 7.3145334e+09 | E5: =C5/B5 -> 3.2972503 | F5: =D5/B5 -> 3012.5743 | G5: =F5/E5 -> 913.66261 | H5: 0.37011615 | I5: =(B5/('Consumidores Inadimplentes'!B41*1000000)) -> 0.039052399
A6: 43525 | B6: 2462740 | C6: 8106614 | D6: 7.4938891e+09 | E6: =C6/B6 -> 3.2917052 | F6: =D6/B6 -> 3042.9071 | G6: =F6/E6 -> 924.41667 | H6: 0.37483496 | I6: =(B6/('Consumidores Inadimplentes'!B42*1000000)) -> 0.039115896
A7: 43556 | B7: 2528830 | C7: 8185086 | D7: 7.4823654e+09 | E7: =C7/B7 -> 3.2367087 | F7: =D7/B7 -> 2958.825 | G7: =F7/E7 -> 914.14622 | H7: 0.38415429 | I7: =(B7/('Consumidores Inadimplentes'!B43*1000000)) -> 0.040009712
A8: 43586 | B8: 2505979 | C8: 8132198 | D8: 7.6400823e+09 | E8: =C8/B8 -> 3.2451182 | F8: =D8/B8 -> 3048.7415 | G8: =F8/E8 -> 939.48552 | H8: 0.37757549 | I8: =(B8/('Consumidores Inadimplentes'!B44*1000000)) -> 0.039542313
A9: 43617 | B9: 2518497 | C9: 8144403 | D9: 7.6976635e+09 | E9: =C9/B9 -> 3.2338347 | F9: =D9/B9 -> 3056.4513 | G9: =F9/E9 -> 945.14767 | H9: 0.38195996 | I9: =(B9/('Consumidores Inadimplentes'!B45*1000000)) -> 0.039692261
A10: 43647 | B10: 2464511 | C10: 7977807 | D10: 7.6724582e+09 | E10: =C10/B10 -> 3.237075 | F10: =D10/B10 -> 3113.1767 | G10: =F10/E10 -> 961.72522 | H10: 0.37294673 | I10: =(B10/('Consumidores Inadimplentes'!B46*1000000)) -> 0.038833599
A11: 43678 | B11: 2432650 | C11: 7723485 | D11: 7.8061925e+09 | E11: =C11/B11 -> 3.1749265 | F11: =D11/B11 -> 3208.9255 | G11: =F11/E11 -> 1010.7086 | H11: 0.36668706 | I11: =(B11/('Consumidores Inadimplentes'!B47*1000000)) -> 0.038352972
A12: 43709 | B12: 2396269 | C12: 7526030 | D12: 7.6877195e+09 | E12: =C12/B12 -> 3.1407284 | F12: =D12/B12 -> 3208.2039 | G12: =F12/E12 -> 1021.484 | H12: 0.36085427 | I12: =(B12/('Consumidores Inadimplentes'!B48*1000000)) -> 0.037911684
A13: 43739 | B13: 2413621 | C13: 7523278 | D13: 7.7460576e+09 | E13: =C13/B13 -> 3.1170088 | F13: =D13/B13 -> 3209.3098 | G13: =F13/E13 -> 1029.612 | H13: 0.36311625 | I13: =(B13/('Consumidores Inadimplentes'!B49*1000000)) -> 0.03780059
A14: 43770 | B14: 2368030 | C14: 7326159 | D14: 7.6803556e+09 | E14: =C14/B14 -> 3.093778 | F14: =D14/B14 -> 3243.3523 | G14: =F14/E14 -> 1048.3468 | H14: 0.35591325 | I14: =(B14/('Consumidores Inadimplentes'!B50*1000000)) -> 0.037092639
A15: 43800 | B15: 2344545 | C15: 7160246 | D15: 7.6524737e+09 | E15: =C15/B15 -> 3.0540024 | F15: =D15/B15 -> 3263.9483 | G15: =F15/E15 -> 1068.7445 | H15: 0.35204314 | I15: =(B15/('Consumidores Inadimplentes'!B51*1000000)) -> 0.037034329
... A83: 45870 | B83: 3645164 | C83: 13489588 | D83: 17789336156 | E83: =C83/B83 -> 3.7006807 | F83: =D83/B83 -> 4880.2567 | G83: =F83/E83 -> 1318.7457 | H83: 0.5181092 | I83: =(B83/('Consumidores Inadimplentes'!B119*1000000)) -> 0.046229772
A84: 45901 | B84: 3684260 | C84: 13717957 | D84: 17919011907 | E84: =IFERROR(C84/B84,"") -> 3.7233955 | F84: =IFERROR(D84/B84,"") -> 4863.6665 | G84: =IFERROR(F84/E84,"") -> 1306.2449 | H84: 0.52326609 | I84: =(B84/('Consumidores Inadimplentes'!B120*1000000)) -> 0.046537853
A85: 45931 | B85: 3654332 | C85: 13836024 | D85: 18251504235 | E85: =IFERROR(C85/B85,"") -> 3.7861979 | F85: =IFERROR(D85/B85,"") -> 4994.4844 | G85: =IFERROR(F85/E85,"") -> 1319.1293 | H85: 0.51861899 | I85: =(B85/('Consumidores Inadimplentes'!B121*1000000)) -> 0.045431248
A86: 45962 | B86: 3637489 | C86: 13580112 | D86: 17720290645 | E86: =IFERROR(C86/B86,"") -> 3.7333754 | F86: =IFERROR(D86/B86,"") -> 4871.5723 | G86: =IFERROR(F86/E86,"") -> 1304.8707 | H86: 0.51583421 | I86: =(B86/('Consumidores Inadimplentes'!B122*1000000)) -> 0.045124613
A87: 45992 | B87: 3707573 | C87: 13972363 | D87: 18045338470 | E87: =IFERROR(C87/B87,"") -> 3.7686009 | F87: =IFERROR(D87/B87,"") -> 4867.1566 | G87: =IFERROR(F87/E87,"") -> 1291.5023 | H87: 0.52537114 | I87: =(B87/('Consumidores Inadimplentes'!B123*1000000)) -> 0.045632782
A88: 46023 | B88: 3578465 | C88: 13340434 | D88: 17606163413 | E88: =IFERROR(C88/B88,"") -> 3.7279767 | F88: =IFERROR(D88/B88,"") -> 4920.0323 | G88: =IFERROR(F88/E88,"") -> 1319.7594 | H88: 0.50668883 | I88: =(B88/('Consumidores Inadimplentes'!B124*1000000)) -> 0.044005095
A89: 46054 | B89: 3655105 | C89: 13761574 | D89: 18150664353 | E89: =IFERROR(C89/B89,"") -> 3.7650284 | F89: =IFERROR(D89/B89,"") -> 4965.8394 | G89: =IFERROR(F89/E89,"") -> 1318.9381 | H89: 0.51714517 | I89: =(B89/('Consumidores Inadimplentes'!B125*1000000)) -> 0.044720657
A90: 46082 | B90: 3768231 | C90: 14390338 | D90: 18876610861 | E90: =IFERROR(C90/B90,"") -> 3.8188577 | F90: =IFERROR(D90/B90,"") -> 5009.4092 | G90: =IFERROR(F90/E90,"") -> 1311.7559 | H90: 0.53274355 | I90: =(B90/('Consumidores Inadimplentes'!B126*1000000)) -> 0.045492185
A91: 46113 | B91: 3762991 | C91: 14515687 | D91: 19171346047 | E91: =IFERROR(C91/B91,"") -> 3.8574865 | F91: =IFERROR(D91/B91,"") -> 5094.7095 | G91: =IFERROR(F91/E91,"") -> 1320.7329 | H91: 0.53159629 | I91: =(B91/('Consumidores Inadimplentes'!B127*1000000)) -> 0.045125644
A92: 46143 | B92: 3714610 | C92: 14393392 | D92: 19214312741 | E92: =IFERROR(C92/B92,"") -> 3.8748057 | F92: =IFERROR(D92/B92,"") -> 5172.6326 | G92: =IFERROR(F92/E92,"") -> 1334.9399 | H92: 0.52436063 | I92: =(B92/('Consumidores Inadimplentes'!B128*1000000)) -> 0.044484831
A93: 46174 | B93: 3732833 | C93: 14424032 | D93: 19341291105 | E93: =IFERROR(C93/B93,"") -> 3.8640979 | F93: =IFERROR(D93/B93,"") -> 5181.3974 | G93: =IFERROR(F93/E93,"") -> 1340.9074 | H93: 0.52653047 | I93: =(B93/('Consumidores Inadimplentes'!B129*1000000)) -> 0.044577744
A94: 46204 | B94: 3735018 | C94: 14521040 | D94: 19416651813 | E94: =IFERROR(C94/B94,"") -> 3.8878099 | F94: =IFERROR(D94/B94,"") -> 5198.543 | G94: =IFERROR(F94/E94,"") -> 1337.1392 | H94: 0.52643605 | I94: =(B94/('Consumidores Inadimplentes'!B130*1000000)) -> 0.044500568
A95: 46235
A96: 46266
A97: 46296
A98: 46327
A99: 46357

Sheet DF
A2: Indicador Serasa Experian de Inadimplência do Consumidor - Distrito Federal
A3: Mês | B3: Consumidores Inadimplentes | C3: Dívidas Negativadas | D3: Dívidas Negativadas (R$) | E3: Dívida Média (por CPF) | F3: Dívida Média (R$) | G3: Ticket Médio (R$) | H3: % da População Adulta | I3: % da População Inadimplente
A4: 43466 | B4: 1008153 | C4: 4059765 | D4: 6.1097571e+09 | E4: =C4/B4 -> 4.0269334 | F4: =D4/B4 -> 6060.3471 | G4: =F4/E4 -> 1504.9534 | H4: 0.47377715 | I4: =(B4/('Consumidores Inadimplentes'!B40*1000000)) -> 0.016214403
A5: 43497 | B5: 1016249 | C5: 4085729 | D5: 6.0872602e+09 | E5: =C5/B5 -> 4.0204015 | F5: =D5/B5 -> 5989.9299 | G5: =F5/E5 -> 1489.8835 | H5: 0.47691636 | I5: =(B5/('Consumidores Inadimplentes'!B41*1000000)) -> 0.016345529
A6: 43525 | B6: 1027167 | C6: 4134193 | D6: 6.2402084e+09 | E6: =C6/B6 -> 4.0248499 | F6: =D6/B6 -> 6075.1644 | G6: =F6/E6 -> 1509.4139 | H6: 0.48130613 | I6: =(B6/('Consumidores Inadimplentes'!B42*1000000)) -> 0.016314576
A7: 43556 | B7: 1010975 | C7: 4135682 | D7: 6.2303056e+09 | E7: =C7/B7 -> 4.0907856 | F7: =D7/B7 -> 6162.6703 | G7: =F7/E7 -> 1506.476 | H7: 0.47276305 | I7: =(B7/('Consumidores Inadimplentes'!B43*1000000)) -> 0.015995072
A8: 43586 | B8: 1017812 | C8: 4150563 | D8: 6.2840031e+09 | E8: =C8/B8 -> 4.077927 | F8: =D8/B8 -> 6174.0313 | G8: =F8/E8 -> 1514.0122 | H8: 0.47242545 | I8: =(B8/('Consumidores Inadimplentes'!B44*1000000)) -> 0.016060246
A9: 43617 | B9: 1017735 | C9: 4216144 | D9: 6.2996051e+09 | E9: =C9/B9 -> 4.1426737 | F9: =D9/B9 -> 6189.8285 | G9: =F9/E9 -> 1494.1627 | H9: 0.47627122 | I9: =(B9/('Consumidores Inadimplentes'!B45*1000000)) -> 0.016039806
A10: 43647 | B10: 1019025 | C10: 4407968 | D10: 6.3029479e+09 | E10: =C10/B10 -> 4.3256721 | F10: =D10/B10 -> 6185.273 | G10: =F10/E10 -> 1429.8987 | H10: 0.47609502 | I10: =(B10/('Consumidores Inadimplentes'!B46*1000000)) -> 0.016056901
A11: 43678 | B11: 1023445 | C11: 4634465 | D11: 6.3566915e+09 | E11: =C11/B11 -> 4.528299 | F11: =D11/B11 -> 6211.0729 | G11: =F11/E11 -> 1371.6128 | H11: 0.47731479 | I11: =(B11/('Consumidores Inadimplentes'!B47*1000000)) -> 0.016135555
A12: 43709 | B12: 1027015 | C12: 4624838 | D12: 6.2772937e+09 | E12: =C12/B12 -> 4.5031845 | F12: =D12/B12 -> 6112.1734 | G12: =F12/E12 -> 1357.3002 | H12: 0.47842017 | I12: =(B12/('Consumidores Inadimplentes'!B48*1000000)) -> 0.016248538
A13: 43739 | B13: 1044739 | C13: 4839724 | D13: 6.3685633e+09 | E13: =C13/B13 -> 4.6324718 | F13: =D13/B13 -> 6095.8415 | G13: =F13/E13 -> 1315.8939 | H13: 0.48610825 | I13: =(B13/('Consumidores Inadimplentes'!B49*1000000)) -> 0.016362035
A14: 43770 | B14: 1055497 | C14: 4899984 | D14: 6.408089e+09 | E14: =C14/B14 -> 4.6423476 | F14: =D14/B14 -> 6071.158 | G14: =F14/E14 -> 1307.7775 | H14: 0.49054028 | I14: =(B14/('Consumidores Inadimplentes'!B50*1000000)) -> 0.016533224
A15: 43800 | B15: 1062155 | C15: 5051904 | D15: 6.4787275e+09 | E15: =C15/B15 -> 4.7562776 | F15: =D15/B15 -> 6099.6064 | G15: =F15/E15 -> 1282.4328 | H15: 0.49305804 | I15: =(B15/('Consumidores Inadimplentes'!B51*1000000)) -> 0.016777754
... A83: 45870 | B83: 1412540 | C83: 8868062 | D83: 12466898790 | E83: =C83/B83 -> 6.2780962 | F83: =D83/B83 -> 8825.8731 | G83: =F83/E83 -> 1405.82 | H83: 0.61199493 | I83: =(B83/('Consumidores Inadimplentes'!B119*1000000)) -> 0.01791453
A84: 45901 | B84: 1410480 | C84: 8887181 | D84: 12433149906 | E84: =IFERROR(C84/B84,"") -> 6.3008203 | F84: =IFERROR(D84/B84,"") -> 8814.836 | G84: =IFERROR(F84/E84,"") -> 1398.9982 | H84: 0.61054798 | I84: =(B84/('Consumidores Inadimplentes'!B120*1000000)) -> 0.017816525
A85: 45931 | B85: 1428130 | C85: 9065486 | D85: 12720842520 | E85: =IFERROR(C85/B85,"") -> 6.3478017 | F85: =IFERROR(D85/B85,"") -> 8907.3421 | G85: =IFERROR(F85/E85,"") -> 1403.2168 | H85: 0.61762715 | I85: =(B85/('Consumidores Inadimplentes'!B121*1000000)) -> 0.017754744
A86: 45962 | B86: 1429848 | C86: 9210736 | D86: 12829843376 | E86: =IFERROR(C86/B86,"") -> 6.4417588 | F86: =IFERROR(D86/B86,"") -> 8972.8722 | G86: =IFERROR(F86/E86,"") -> 1392.9227 | H86: 0.61780905 | I86: =(B86/('Consumidores Inadimplentes'!B122*1000000)) -> 0.017737878
A87: 45992 | B87: 1432411 | C87: 9323845 | D87: 13000854502 | E87: =IFERROR(C87/B87,"") -> 6.5091967 | F87: =IFERROR(D87/B87,"") -> 9076.204 | G87: =IFERROR(F87/E87,"") -> 1394.3662 | H87: 0.61835486 | I87: =(B87/('Consumidores Inadimplentes'!B123*1000000)) -> 0.017630104
A88: 46023 | B88: 1435211 | C88: 9447626 | D88: 13139727442 | E88: =IFERROR(C88/B88,"") -> 6.5827436 | F88: =IFERROR(D88/B88,"") -> 9155.2583 | G88: =IFERROR(F88/E88,"") -> 1390.7967 | H88: 0.61900137 | I88: =(B88/('Consumidores Inadimplentes'!B124*1000000)) -> 0.017649075
A89: 46054 | B89: 1441446 | C89: 9517415 | D89: 13363810053 | E89: =IFERROR(C89/B89,"") -> 6.6026858 | F89: =IFERROR(D89/B89,"") -> 9271.1139 | G89: =IFERROR(F89/E89,"") -> 1404.1428 | H89: 0.62112633 | I89: =(B89/('Consumidores Inadimplentes'!B125*1000000)) -> 0.017636268
